{
    DataVersion: 3337,
    size: [4, 4, 4],
    data: [
        {pos: [0, 0, 0], state: "ae2:pattern_provider{push_direction:all}", nbt: {blocking_mode: "NO", id: "ae2:pattern_provider", lock_crafting_mode: "NONE", pattern_access_terminal: "YES", priority: 0, returnInv: [], sendList: [], visual: {}}},
        {pos: [1, 0, 0], state: "appliedpackaging:package_assembler{facing:north}", nbt: {blocking_mode: 0b, id: "appliedpackaging:package_assembler", output_mode: "me_network", selected_color: "fluix"}},
        {pos: [2, 0, 0], state: "ae2:pattern_provider{push_direction:all}", nbt: {blocking_mode: "NO", id: "ae2:pattern_provider", lock_crafting_mode: "NONE", pattern_access_terminal: "YES", priority: 0, returnInv: [], sendList: [], visual: {}}},
        {pos: [3, 0, 0], state: "appliedpackaging:package_assembler{facing:north}", nbt: {blocking_mode: 0b, id: "appliedpackaging:package_assembler", output_mode: "me_network", selected_color: "fluix"}},
        {pos: [0, 0, 1], state: "appliedpackaging:package_assembler{facing:north}", nbt: {blocking_mode: 0b, id: "appliedpackaging:package_assembler", output_mode: "me_network", selected_color: "fluix"}},
        {pos: [1, 0, 1], state: "ae2:pattern_provider{push_direction:all}", nbt: {blocking_mode: "NO", id: "ae2:pattern_provider", lock_crafting_mode: "NONE", pattern_access_terminal: "YES", priority: 0, returnInv: [], sendList: [], visual: {}}},
        {pos: [2, 0, 1], state: "appliedpackaging:package_assembler{facing:north}", nbt: {blocking_mode: 0b, id: "appliedpackaging:package_assembler", output_mode: "me_network", selected_color: "fluix"}},
        {pos: [3, 0, 1], state: "ae2:pattern_provider{push_direction:all}", nbt: {blocking_mode: "NO", id: "ae2:pattern_provider", lock_crafting_mode: "NONE", pattern_access_terminal: "YES", priority: 0, returnInv: [], sendList: [], visual: {}}},
        {pos: [0, 0, 2], state: "ae2:pattern_provider{push_direction:all}", nbt: {blocking_mode: "NO", id: "ae2:pattern_provider", lock_crafting_mode: "NONE", pattern_access_terminal: "YES", priority: 0, returnInv: [], sendList: [], visual: {}}},
        {pos: [1, 0, 2], state: "appliedpackaging:package_assembler{facing:north}", nbt: {blocking_mode: 0b, id: "appliedpackaging:package_assembler", output_mode: "me_network", selected_color: "fluix"}},
        {pos: [2, 0, 2], state: "ae2:pattern_provider{push_direction:all}", nbt: {blocking_mode: "NO", id: "ae2:pattern_provider", lock_crafting_mode: "NONE", pattern_access_terminal: "YES", priority: 0, returnInv: [], sendList: [], visual: {}}},
        {pos: [3, 0, 2], state: "appliedpackaging:package_assembler{facing:north}", nbt: {blocking_mode: 0b, id: "appliedpackaging:package_assembler", output_mode: "me_network", selected_color: "fluix"}},
        {pos: [0, 0, 3], state: "appliedpackaging:package_assembler{facing:north}", nbt: {blocking_mode: 0b, id: "appliedpackaging:package_assembler", output_mode: "me_network", selected_color: "fluix"}},
        {pos: [1, 0, 3], state: "ae2:pattern_provider{push_direction:all}", nbt: {blocking_mode: "NO", id: "ae2:pattern_provider", lock_crafting_mode: "NONE", pattern_access_terminal: "YES", priority: 0, returnInv: [], sendList: [], visual: {}}},
        {pos: [2, 0, 3], state: "appliedpackaging:package_assembler{facing:north}", nbt: {blocking_mode: 0b, id: "appliedpackaging:package_assembler", output_mode: "me_network", selected_color: "fluix"}},
        {pos: [3, 0, 3], state: "ae2:pattern_provider{push_direction:all}", nbt: {blocking_mode: "NO", id: "ae2:pattern_provider", lock_crafting_mode: "NONE", pattern_access_terminal: "YES", priority: 0, returnInv: [], sendList: [], visual: {}}},
        {pos: [0, 1, 0], state: "appliedpackaging:package_assembler{facing:north}", nbt: {blocking_mode: 0b, id: "appliedpackaging:package_assembler", output_mode: "me_network", selected_color: "fluix"}},
        {pos: [1, 1, 0], state: "ae2:pattern_provider{push_direction:all}", nbt: {blocking_mode: "NO", id: "ae2:pattern_provider", lock_crafting_mode: "NONE", pattern_access_terminal: "YES", priority: 0, returnInv: [], sendList: [], visual: {}}},
        {pos: [2, 1, 0], state: "appliedpackaging:package_assembler{facing:north}", nbt: {blocking_mode: 0b, id: "appliedpackaging:package_assembler", output_mode: "me_network", selected_color: "fluix"}},
        {pos: [3, 1, 0], state: "ae2:pattern_provider{push_direction:all}", nbt: {blocking_mode: "NO", id: "ae2:pattern_provider", lock_crafting_mode: "NONE", pattern_access_terminal: "YES", priority: 0, returnInv: [], sendList: [], visual: {}}},
        {pos: [0, 1, 1], state: "ae2:pattern_provider{push_direction:all}", nbt: {blocking_mode: "NO", id: "ae2:pattern_provider", lock_crafting_mode: "NONE", pattern_access_terminal: "YES", priority: 0, returnInv: [], sendList: [], visual: {}}},
        {pos: [1, 1, 1], state: "appliedpackaging:package_assembler{facing:north}", nbt: {blocking_mode: 0b, id: "appliedpackaging:package_assembler", output_mode: "me_network", selected_color: "fluix"}},
        {pos: [2, 1, 1], state: "ae2:pattern_provider{push_direction:all}", nbt: {blocking_mode: "NO", id: "ae2:pattern_provider", lock_crafting_mode: "NONE", pattern_access_terminal: "YES", priority: 0, returnInv: [], sendList: [], visual: {}}},
        {pos: [3, 1, 1], state: "appliedpackaging:package_assembler{facing:north}", nbt: {blocking_mode: 0b, id: "appliedpackaging:package_assembler", output_mode: "me_network", selected_color: "fluix"}},
        {pos: [0, 1, 2], state: "appliedpackaging:package_assembler{facing:north}", nbt: {blocking_mode: 0b, id: "appliedpackaging:package_assembler", output_mode: "me_network", selected_color: "fluix"}},
        {pos: [1, 1, 2], state: "ae2:pattern_provider{push_direction:all}", nbt: {blocking_mode: "NO", id: "ae2:pattern_provider", lock_crafting_mode: "NONE", pattern_access_terminal: "YES", priority: 0, returnInv: [], sendList: [], visual: {}}},
        {pos: [2, 1, 2], state: "appliedpackaging:package_assembler{facing:north}", nbt: {blocking_mode: 0b, id: "appliedpackaging:package_assembler", output_mode: "me_network", selected_color: "fluix"}},
        {pos: [3, 1, 2], state: "ae2:pattern_provider{push_direction:all}", nbt: {blocking_mode: "NO", id: "ae2:pattern_provider", lock_crafting_mode: "NONE", pattern_access_terminal: "YES", priority: 0, returnInv: [], sendList: [], visual: {}}},
        {pos: [0, 1, 3], state: "ae2:pattern_provider{push_direction:all}", nbt: {blocking_mode: "NO", id: "ae2:pattern_provider", lock_crafting_mode: "NONE", pattern_access_terminal: "YES", priority: 0, returnInv: [], sendList: [], visual: {}}},
        {pos: [1, 1, 3], state: "appliedpackaging:package_assembler{facing:north}", nbt: {blocking_mode: 0b, id: "appliedpackaging:package_assembler", output_mode: "me_network", selected_color: "fluix"}},
        {pos: [2, 1, 3], state: "ae2:pattern_provider{push_direction:all}", nbt: {blocking_mode: "NO", id: "ae2:pattern_provider", lock_crafting_mode: "NONE", pattern_access_terminal: "YES", priority: 0, returnInv: [], sendList: [], visual: {}}},
        {pos: [3, 1, 3], state: "appliedpackaging:package_assembler{facing:north}", nbt: {blocking_mode: 0b, id: "appliedpackaging:package_assembler", output_mode: "me_network", selected_color: "fluix"}},
        {pos: [0, 2, 0], state: "ae2:pattern_provider{push_direction:all}", nbt: {blocking_mode: "NO", id: "ae2:pattern_provider", lock_crafting_mode: "NONE", pattern_access_terminal: "YES", priority: 0, returnInv: [], sendList: [], visual: {}}},
        {pos: [1, 2, 0], state: "appliedpackaging:package_assembler{facing:north}", nbt: {blocking_mode: 0b, id: "appliedpackaging:package_assembler", output_mode: "me_network", selected_color: "fluix"}},
        {pos: [2, 2, 0], state: "ae2:pattern_provider{push_direction:all}", nbt: {blocking_mode: "NO", id: "ae2:pattern_provider", lock_crafting_mode: "NONE", pattern_access_terminal: "YES", priority: 0, returnInv: [], sendList: [], visual: {}}},
        {pos: [3, 2, 0], state: "appliedpackaging:package_assembler{facing:north}", nbt: {blocking_mode: 0b, id: "appliedpackaging:package_assembler", output_mode: "me_network", selected_color: "fluix"}},
        {pos: [0, 2, 1], state: "appliedpackaging:package_assembler{facing:north}", nbt: {blocking_mode: 0b, id: "appliedpackaging:package_assembler", output_mode: "me_network", selected_color: "fluix"}},
        {pos: [1, 2, 1], state: "ae2:pattern_provider{push_direction:all}", nbt: {blocking_mode: "NO", id: "ae2:pattern_provider", lock_crafting_mode: "NONE", pattern_access_terminal: "YES", priority: 0, returnInv: [], sendList: [], visual: {}}},
        {pos: [2, 2, 1], state: "appliedpackaging:package_assembler{facing:north}", nbt: {blocking_mode: 0b, id: "appliedpackaging:package_assembler", output_mode: "me_network", selected_color: "fluix"}},
        {pos: [3, 2, 1], state: "ae2:pattern_provider{push_direction:all}", nbt: {blocking_mode: "NO", id: "ae2:pattern_provider", lock_crafting_mode: "NONE", pattern_access_terminal: "YES", priority: 0, returnInv: [], sendList: [], visual: {}}},
        {pos: [0, 2, 2], state: "ae2:pattern_provider{push_direction:all}", nbt: {blocking_mode: "NO", id: "ae2:pattern_provider", lock_crafting_mode: "NONE", pattern_access_terminal: "YES", priority: 0, returnInv: [], sendList: [], visual: {}}},
        {pos: [1, 2, 2], state: "appliedpackaging:package_assembler{facing:north}", nbt: {blocking_mode: 0b, id: "appliedpackaging:package_assembler", output_mode: "me_network", selected_color: "fluix"}},
        {pos: [2, 2, 2], state: "ae2:pattern_provider{push_direction:all}", nbt: {blocking_mode: "NO", id: "ae2:pattern_provider", lock_crafting_mode: "NONE", pattern_access_terminal: "YES", priority: 0, returnInv: [], sendList: [], visual: {}}},
        {pos: [3, 2, 2], state: "appliedpackaging:package_assembler{facing:north}", nbt: {blocking_mode: 0b, id: "appliedpackaging:package_assembler", output_mode: "me_network", selected_color: "fluix"}},
        {pos: [0, 2, 3], state: "appliedpackaging:package_assembler{facing:north}", nbt: {blocking_mode: 0b, id: "appliedpackaging:package_assembler", output_mode: "me_network", selected_color: "fluix"}},
        {pos: [1, 2, 3], state: "ae2:pattern_provider{push_direction:all}", nbt: {blocking_mode: "NO", id: "ae2:pattern_provider", lock_crafting_mode: "NONE", pattern_access_terminal: "YES", priority: 0, returnInv: [], sendList: [], visual: {}}},
        {pos: [2, 2, 3], state: "appliedpackaging:package_assembler{facing:north}", nbt: {blocking_mode: 0b, id: "appliedpackaging:package_assembler", output_mode: "me_network", selected_color: "fluix"}},
        {pos: [3, 2, 3], state: "ae2:pattern_provider{push_direction:all}", nbt: {blocking_mode: "NO", id: "ae2:pattern_provider", lock_crafting_mode: "NONE", pattern_access_terminal: "YES", priority: 0, returnInv: [], sendList: [], visual: {}}},
        {pos: [0, 3, 0], state: "appliedpackaging:package_assembler{facing:north}", nbt: {blocking_mode: 0b, id: "appliedpackaging:package_assembler", output_mode: "me_network", selected_color: "fluix"}},
        {pos: [1, 3, 0], state: "ae2:pattern_provider{push_direction:all}", nbt: {blocking_mode: "NO", id: "ae2:pattern_provider", lock_crafting_mode: "NONE", pattern_access_terminal: "YES", priority: 0, returnInv: [], sendList: [], visual: {}}},
        {pos: [2, 3, 0], state: "appliedpackaging:package_assembler{facing:north}", nbt: {blocking_mode: 0b, id: "appliedpackaging:package_assembler", output_mode: "me_network", selected_color: "fluix"}},
        {pos: [3, 3, 0], state: "ae2:pattern_provider{push_direction:all}", nbt: {blocking_mode: "NO", id: "ae2:pattern_provider", lock_crafting_mode: "NONE", pattern_access_terminal: "YES", priority: 0, returnInv: [], sendList: [], visual: {}}},
        {pos: [0, 3, 1], state: "ae2:pattern_provider{push_direction:all}", nbt: {blocking_mode: "NO", id: "ae2:pattern_provider", lock_crafting_mode: "NONE", pattern_access_terminal: "YES", priority: 0, returnInv: [], sendList: [], visual: {}}},
        {pos: [1, 3, 1], state: "appliedpackaging:package_assembler{facing:north}", nbt: {blocking_mode: 0b, id: "appliedpackaging:package_assembler", output_mode: "me_network", selected_color: "fluix"}},
        {pos: [2, 3, 1], state: "ae2:pattern_provider{push_direction:all}", nbt: {blocking_mode: "NO", id: "ae2:pattern_provider", lock_crafting_mode: "NONE", pattern_access_terminal: "YES", priority: 0, returnInv: [], sendList: [], visual: {}}},
        {pos: [3, 3, 1], state: "appliedpackaging:package_assembler{facing:north}", nbt: {blocking_mode: 0b, id: "appliedpackaging:package_assembler", output_mode: "me_network", selected_color: "fluix"}},
        {pos: [0, 3, 2], state: "appliedpackaging:package_assembler{facing:north}", nbt: {blocking_mode: 0b, id: "appliedpackaging:package_assembler", output_mode: "me_network", selected_color: "fluix"}},
        {pos: [1, 3, 2], state: "ae2:pattern_provider{push_direction:all}", nbt: {blocking_mode: "NO", id: "ae2:pattern_provider", lock_crafting_mode: "NONE", pattern_access_terminal: "YES", priority: 0, returnInv: [], sendList: [], visual: {}}},
        {pos: [2, 3, 2], state: "appliedpackaging:package_assembler{facing:north}", nbt: {blocking_mode: 0b, id: "appliedpackaging:package_assembler", output_mode: "me_network", selected_color: "fluix"}},
        {pos: [3, 3, 2], state: "ae2:pattern_provider{push_direction:all}", nbt: {blocking_mode: "NO", id: "ae2:pattern_provider", lock_crafting_mode: "NONE", pattern_access_terminal: "YES", priority: 0, returnInv: [], sendList: [], visual: {}}},
        {pos: [0, 3, 3], state: "ae2:pattern_provider{push_direction:all}", nbt: {blocking_mode: "NO", id: "ae2:pattern_provider", lock_crafting_mode: "NONE", pattern_access_terminal: "YES", priority: 0, returnInv: [], sendList: [], visual: {}}},
        {pos: [1, 3, 3], state: "appliedpackaging:package_assembler{facing:north}", nbt: {blocking_mode: 0b, id: "appliedpackaging:package_assembler", output_mode: "me_network", selected_color: "fluix"}},
        {pos: [2, 3, 3], state: "ae2:pattern_provider{push_direction:all}", nbt: {blocking_mode: "NO", id: "ae2:pattern_provider", lock_crafting_mode: "NONE", pattern_access_terminal: "YES", priority: 0, returnInv: [], sendList: [], visual: {}}},
        {pos: [3, 3, 3], state: "appliedpackaging:package_assembler{facing:north}", nbt: {blocking_mode: 0b, id: "appliedpackaging:package_assembler", output_mode: "me_network", selected_color: "fluix"}}
    ],
    entities: [],
    palette: [
        "ae2:pattern_provider{push_direction:all}",
        "appliedpackaging:package_assembler{facing:north}"
    ]
}
